2025-06-01 23:50:50,010 - INFO - Testing backend direct access with session ID: test_session_539991
2025-06-01 23:50:50,013 - INFO - Testing health endpoint...
Traceback (most recent call last):
  File "C:\Users\dayour\AppData\Local\Programs\Python\Python312\Lib\site-packages\aiohttp\connector.py", line 1115, in _wrap_create_connection
    sock = await aiohappyeyeballs.start_connection(
           ^^^^^^^^^^^^^^^^^^^^^^^^^^^^^^^^^^^^^^^^
  File "C:\Users\dayour\AppData\Local\Programs\Python\Python312\Lib\site-packages\aiohappyeyeballs\impl.py", line 127, in start_connection
    raise first_exception
  File "C:\Users\dayour\AppData\Local\Programs\Python\Python312\Lib\site-packages\aiohappyeyeballs\_staggered.py", line 132, in run_one_coro
    result = await coro_fn()
             ^^^^^^^^^^^^^^^
  File "C:\Users\dayour\AppData\Local\Programs\Python\Python312\Lib\site-packages\aiohappyeyeballs\impl.py", line 208, in _connect_sock
    await loop.sock_connect(sock, address)
  File "C:\Users\dayour\AppData\Local\Programs\Python\Python312\Lib\asyncio\proactor_events.py", line 729, in sock_connect
    return await self._proactor.connect(sock, address)
           ^^^^^^^^^^^^^^^^^^^^^^^^^^^^^^^^^^^^^^^^^^^
  File "C:\Users\dayour\AppData\Local\Programs\Python\Python312\Lib\asyncio\windows_events.py", line 803, in _poll
    value = callback(transferred, key, ov)
            ^^^^^^^^^^^^^^^^^^^^^^^^^^^^^^
  File "C:\Users\dayour\AppData\Local\Programs\Python\Python312\Lib\asyncio\windows_events.py", line 599, in finish_connect
    ov.getresult()
ConnectionRefusedError: [WinError 1225] The remote computer refused the network connection

The above exception was the direct cause of the following exception:

Traceback (most recent call last):
  File "D:\0GH_PROD\Darbot-Agent-Engine\debug_backend_api.py", line 78, in <module>
    asyncio.run(test_backend_direct())
  File "C:\Users\dayour\AppData\Local\Programs\Python\Python312\Lib\asyncio\runners.py", line 195, in run
    return runner.run(main)
           ^^^^^^^^^^^^^^^^
  File "C:\Users\dayour\AppData\Local\Programs\Python\Python312\Lib\asyncio\runners.py", line 118, in run
    return self._loop.run_until_complete(task)
           ^^^^^^^^^^^^^^^^^^^^^^^^^^^^^^^^^^^
  File "C:\Users\dayour\AppData\Local\Programs\Python\Python312\Lib\asyncio\base_events.py", line 691, in run_until_complete
    return future.result()
           ^^^^^^^^^^^^^^^
  File "D:\0GH_PROD\Darbot-Agent-Engine\debug_backend_api.py", line 20, in test_backend_direct
    async with session.get(f"{backend_url}/health") as response:
               ^^^^^^^^^^^^^^^^^^^^^^^^^^^^^^^^^^^^
  File "C:\Users\dayour\AppData\Local\Programs\Python\Python312\Lib\site-packages\aiohttp\client.py", line 1425, in __aenter__
    self._resp: _RetType = await self._coro
                           ^^^^^^^^^^^^^^^^
  File "C:\Users\dayour\AppData\Local\Programs\Python\Python312\Lib\site-packages\aiohttp\client.py", line 703, in _request
    conn = await self._connector.connect(
           ^^^^^^^^^^^^^^^^^^^^^^^^^^^^^^
  File "C:\Users\dayour\AppData\Local\Programs\Python\Python312\Lib\site-packages\aiohttp\connector.py", line 548, in connect
    proto = await self._create_connection(req, traces, timeout)
            ^^^^^^^^^^^^^^^^^^^^^^^^^^^^^^^^^^^^^^^^^^^^^^^^^^^
  File "C:\Users\dayour\AppData\Local\Programs\Python\Python312\Lib\site-packages\aiohttp\connector.py", line 1056, in _create_connection
    _, proto = await self._create_direct_connection(req, traces, timeout)
               ^^^^^^^^^^^^^^^^^^^^^^^^^^^^^^^^^^^^^^^^^^^^^^^^^^^^^^^^^^
  File "C:\Users\dayour\AppData\Local\Programs\Python\Python312\Lib\site-packages\aiohttp\connector.py", line 1406, in _create_direct_connection
    raise last_exc
  File "C:\Users\dayour\AppData\Local\Programs\Python\Python312\Lib\site-packages\aiohttp\connector.py", line 1375, in _create_direct_connection
    transp, proto = await self._wrap_create_connection(
                    ^^^^^^^^^^^^^^^^^^^^^^^^^^^^^^^^^^^
  File "C:\Users\dayour\AppData\Local\Programs\Python\Python312\Lib\site-packages\aiohttp\connector.py", line 1130, in _wrap_create_connection
    raise client_error(req.connection_key, exc) from exc
aiohttp.client_exceptions.ClientConnectorError: Cannot connect to host localhost:8001 ssl:default [The remote computer refused the network connection]
