INFO:     Will watch for changes in these directories: ['D:\\0GH_PROD\\Darbot-Agent-Engine\\src\\frontend']
INFO:     Uvicorn running on http://127.0.0.1:3000 (Press CTRL+C to quit)
INFO:     Started reloader process [109764] using WatchFiles
INFO:     Started server process [69836]
INFO:     Waiting for application startup.
INFO:     Application startup complete.
2025-06-01 23:39:29,138 - root - INFO - Proxying GET request to: http://localhost:8001/api/server-info
2025-06-01 23:39:29,138 - root - INFO - Query params: {}
2025-06-01 23:39:29,147 - root - INFO - Headers: {'accept': '*/*', 'accept-encoding': 'gzip, deflate', 'user-agent': 'Python/3.12 aiohttp/3.11.18'}
2025-06-01 23:39:31,750 - root - ERROR - Proxy error: All connection attempts failed
Traceback (most recent call last):
  File "C:\Users\dayour\AppData\Local\Programs\Python\Python312\Lib\site-packages\httpx\_transports\default.py", line 101, in map_httpcore_exceptions
    yield
  File "C:\Users\dayour\AppData\Local\Programs\Python\Python312\Lib\site-packages\httpx\_transports\default.py", line 394, in handle_async_request
    resp = await self._pool.handle_async_request(req)
           ^^^^^^^^^^^^^^^^^^^^^^^^^^^^^^^^^^^^^^^^^^
  File "C:\Users\dayour\AppData\Local\Programs\Python\Python312\Lib\site-packages\httpcore\_async\connection_pool.py", line 256, in handle_async_request
    raise exc from None
  File "C:\Users\dayour\AppData\Local\Programs\Python\Python312\Lib\site-packages\httpcore\_async\connection_pool.py", line 236, in handle_async_request
    response = await connection.handle_async_request(
               ^^^^^^^^^^^^^^^^^^^^^^^^^^^^^^^^^^^^^^
  File "C:\Users\dayour\AppData\Local\Programs\Python\Python312\Lib\site-packages\httpcore\_async\connection.py", line 101, in handle_async_request
    raise exc
  File "C:\Users\dayour\AppData\Local\Programs\Python\Python312\Lib\site-packages\httpcore\_async\connection.py", line 78, in handle_async_request
    stream = await self._connect(request)
             ^^^^^^^^^^^^^^^^^^^^^^^^^^^^
  File "C:\Users\dayour\AppData\Local\Programs\Python\Python312\Lib\site-packages\httpcore\_async\connection.py", line 124, in _connect
    stream = await self._network_backend.connect_tcp(**kwargs)
             ^^^^^^^^^^^^^^^^^^^^^^^^^^^^^^^^^^^^^^^^^^^^^^^^^
  File "C:\Users\dayour\AppData\Local\Programs\Python\Python312\Lib\site-packages\httpcore\_backends\auto.py", line 31, in connect_tcp
    return await self._backend.connect_tcp(
           ^^^^^^^^^^^^^^^^^^^^^^^^^^^^^^^^
  File "C:\Users\dayour\AppData\Local\Programs\Python\Python312\Lib\site-packages\httpcore\_backends\anyio.py", line 113, in connect_tcp
    with map_exceptions(exc_map):
         ^^^^^^^^^^^^^^^^^^^^^^^
  File "C:\Users\dayour\AppData\Local\Programs\Python\Python312\Lib\contextlib.py", line 158, in __exit__
    self.gen.throw(value)
  File "C:\Users\dayour\AppData\Local\Programs\Python\Python312\Lib\site-packages\httpcore\_exceptions.py", line 14, in map_exceptions
    raise to_exc(exc) from exc
httpcore.ConnectError: All connection attempts failed

The above exception was the direct cause of the following exception:

Traceback (most recent call last):
  File "D:\0GH_PROD\Darbot-Agent-Engine\src\frontend\frontend_server.py", line 109, in api_proxy
    response = await client.request(
               ^^^^^^^^^^^^^^^^^^^^^
  File "C:\Users\dayour\AppData\Local\Programs\Python\Python312\Lib\site-packages\httpx\_client.py", line 1540, in request
    return await self.send(request, auth=auth, follow_redirects=follow_redirects)
           ^^^^^^^^^^^^^^^^^^^^^^^^^^^^^^^^^^^^^^^^^^^^^^^^^^^^^^^^^^^^^^^^^^^^^^
  File "C:\Users\dayour\AppData\Local\Programs\Python\Python312\Lib\site-packages\httpx\_client.py", line 1629, in send
    response = await self._send_handling_auth(
               ^^^^^^^^^^^^^^^^^^^^^^^^^^^^^^^
  File "C:\Users\dayour\AppData\Local\Programs\Python\Python312\Lib\site-packages\httpx\_client.py", line 1657, in _send_handling_auth
    response = await self._send_handling_redirects(
               ^^^^^^^^^^^^^^^^^^^^^^^^^^^^^^^^^^^^
  File "C:\Users\dayour\AppData\Local\Programs\Python\Python312\Lib\site-packages\httpx\_client.py", line 1694, in _send_handling_redirects
    response = await self._send_single_request(request)
               ^^^^^^^^^^^^^^^^^^^^^^^^^^^^^^^^^^^^^^^^
  File "C:\Users\dayour\AppData\Local\Programs\Python\Python312\Lib\site-packages\httpx\_client.py", line 1730, in _send_single_request
    response = await transport.handle_async_request(request)
               ^^^^^^^^^^^^^^^^^^^^^^^^^^^^^^^^^^^^^^^^^^^^^
  File "C:\Users\dayour\AppData\Local\Programs\Python\Python312\Lib\site-packages\httpx\_transports\default.py", line 393, in handle_async_request
    with map_httpcore_exceptions():
         ^^^^^^^^^^^^^^^^^^^^^^^^^
  File "C:\Users\dayour\AppData\Local\Programs\Python\Python312\Lib\contextlib.py", line 158, in __exit__
    self.gen.throw(value)
  File "C:\Users\dayour\AppData\Local\Programs\Python\Python312\Lib\site-packages\httpx\_transports\default.py", line 118, in map_httpcore_exceptions
    raise mapped_exc(message) from exc
httpx.ConnectError: All connection attempts failed
2025-06-01 23:39:31,838 - root - INFO - Proxying POST request to: http://localhost:8001/api/input_task
2025-06-01 23:39:31,838 - root - INFO - Query params: {}
2025-06-01 23:39:31,838 - root - INFO - Headers: {'accept': '*/*', 'accept-encoding': 'gzip, deflate', 'user-agent': 'Python/3.12 aiohttp/3.11.18', 'content-length': '88', 'content-type': 'application/json'}
2025-06-01 23:39:31,838 - root - INFO - Request body: {"session_id": "test_session_1748846369", "description": "Test task via frontend proxy"}
2025-06-01 23:39:34,354 - root - ERROR - Proxy error: All connection attempts failed
Traceback (most recent call last):
  File "C:\Users\dayour\AppData\Local\Programs\Python\Python312\Lib\site-packages\httpx\_transports\default.py", line 101, in map_httpcore_exceptions
    yield
  File "C:\Users\dayour\AppData\Local\Programs\Python\Python312\Lib\site-packages\httpx\_transports\default.py", line 394, in handle_async_request
    resp = await self._pool.handle_async_request(req)
           ^^^^^^^^^^^^^^^^^^^^^^^^^^^^^^^^^^^^^^^^^^
  File "C:\Users\dayour\AppData\Local\Programs\Python\Python312\Lib\site-packages\httpcore\_async\connection_pool.py", line 256, in handle_async_request
    raise exc from None
  File "C:\Users\dayour\AppData\Local\Programs\Python\Python312\Lib\site-packages\httpcore\_async\connection_pool.py", line 236, in handle_async_request
    response = await connection.handle_async_request(
               ^^^^^^^^^^^^^^^^^^^^^^^^^^^^^^^^^^^^^^
  File "C:\Users\dayour\AppData\Local\Programs\Python\Python312\Lib\site-packages\httpcore\_async\connection.py", line 101, in handle_async_request
    raise exc
  File "C:\Users\dayour\AppData\Local\Programs\Python\Python312\Lib\site-packages\httpcore\_async\connection.py", line 78, in handle_async_request
    stream = await self._connect(request)
             ^^^^^^^^^^^^^^^^^^^^^^^^^^^^
  File "C:\Users\dayour\AppData\Local\Programs\Python\Python312\Lib\site-packages\httpcore\_async\connection.py", line 124, in _connect
    stream = await self._network_backend.connect_tcp(**kwargs)
             ^^^^^^^^^^^^^^^^^^^^^^^^^^^^^^^^^^^^^^^^^^^^^^^^^
  File "C:\Users\dayour\AppData\Local\Programs\Python\Python312\Lib\site-packages\httpcore\_backends\auto.py", line 31, in connect_tcp
    return await self._backend.connect_tcp(
           ^^^^^^^^^^^^^^^^^^^^^^^^^^^^^^^^
  File "C:\Users\dayour\AppData\Local\Programs\Python\Python312\Lib\site-packages\httpcore\_backends\anyio.py", line 113, in connect_tcp
    with map_exceptions(exc_map):
         ^^^^^^^^^^^^^^^^^^^^^^^
  File "C:\Users\dayour\AppData\Local\Programs\Python\Python312\Lib\contextlib.py", line 158, in __exit__
    self.gen.throw(value)
  File "C:\Users\dayour\AppData\Local\Programs\Python\Python312\Lib\site-packages\httpcore\_exceptions.py", line 14, in map_exceptions
    raise to_exc(exc) from exc
httpcore.ConnectError: All connection attempts failed

The above exception was the direct cause of the following exception:

Traceback (most recent call last):
  File "D:\0GH_PROD\Darbot-Agent-Engine\src\frontend\frontend_server.py", line 109, in api_proxy
    response = await client.request(
               ^^^^^^^^^^^^^^^^^^^^^
  File "C:\Users\dayour\AppData\Local\Programs\Python\Python312\Lib\site-packages\httpx\_client.py", line 1540, in request
    return await self.send(request, auth=auth, follow_redirects=follow_redirects)
           ^^^^^^^^^^^^^^^^^^^^^^^^^^^^^^^^^^^^^^^^^^^^^^^^^^^^^^^^^^^^^^^^^^^^^^
  File "C:\Users\dayour\AppData\Local\Programs\Python\Python312\Lib\site-packages\httpx\_client.py", line 1629, in send
    response = await self._send_handling_auth(
               ^^^^^^^^^^^^^^^^^^^^^^^^^^^^^^^
  File "C:\Users\dayour\AppData\Local\Programs\Python\Python312\Lib\site-packages\httpx\_client.py", line 1657, in _send_handling_auth
    response = await self._send_handling_redirects(
               ^^^^^^^^^^^^^^^^^^^^^^^^^^^^^^^^^^^^
  File "C:\Users\dayour\AppData\Local\Programs\Python\Python312\Lib\site-packages\httpx\_client.py", line 1694, in _send_handling_redirects
    response = await self._send_single_request(request)
               ^^^^^^^^^^^^^^^^^^^^^^^^^^^^^^^^^^^^^^^^
  File "C:\Users\dayour\AppData\Local\Programs\Python\Python312\Lib\site-packages\httpx\_client.py", line 1730, in _send_single_request
    response = await transport.handle_async_request(request)
               ^^^^^^^^^^^^^^^^^^^^^^^^^^^^^^^^^^^^^^^^^^^^^
  File "C:\Users\dayour\AppData\Local\Programs\Python\Python312\Lib\site-packages\httpx\_transports\default.py", line 393, in handle_async_request
    with map_httpcore_exceptions():
         ^^^^^^^^^^^^^^^^^^^^^^^^^
  File "C:\Users\dayour\AppData\Local\Programs\Python\Python312\Lib\contextlib.py", line 158, in __exit__
    self.gen.throw(value)
  File "C:\Users\dayour\AppData\Local\Programs\Python\Python312\Lib\site-packages\httpx\_transports\default.py", line 118, in map_httpcore_exceptions
    raise mapped_exc(message) from exc
httpx.ConnectError: All connection attempts failed
2025-06-01 23:39:34,361 - root - INFO - Proxying GET request to: http://localhost:8001/api/plans
2025-06-01 23:39:34,361 - root - INFO - Query params: {'session_id': 'test_session_1748846369'}
2025-06-01 23:39:34,361 - root - INFO - Headers: {'accept': '*/*', 'accept-encoding': 'gzip, deflate', 'user-agent': 'Python/3.12 aiohttp/3.11.18'}
2025-06-01 23:39:36,870 - root - ERROR - Proxy error: All connection attempts failed
Traceback (most recent call last):
  File "C:\Users\dayour\AppData\Local\Programs\Python\Python312\Lib\site-packages\httpx\_transports\default.py", line 101, in map_httpcore_exceptions
    yield
  File "C:\Users\dayour\AppData\Local\Programs\Python\Python312\Lib\site-packages\httpx\_transports\default.py", line 394, in handle_async_request
    resp = await self._pool.handle_async_request(req)
           ^^^^^^^^^^^^^^^^^^^^^^^^^^^^^^^^^^^^^^^^^^
  File "C:\Users\dayour\AppData\Local\Programs\Python\Python312\Lib\site-packages\httpcore\_async\connection_pool.py", line 256, in handle_async_request
    raise exc from None
  File "C:\Users\dayour\AppData\Local\Programs\Python\Python312\Lib\site-packages\httpcore\_async\connection_pool.py", line 236, in handle_async_request
    response = await connection.handle_async_request(
               ^^^^^^^^^^^^^^^^^^^^^^^^^^^^^^^^^^^^^^
  File "C:\Users\dayour\AppData\Local\Programs\Python\Python312\Lib\site-packages\httpcore\_async\connection.py", line 101, in handle_async_request
    raise exc
  File "C:\Users\dayour\AppData\Local\Programs\Python\Python312\Lib\site-packages\httpcore\_async\connection.py", line 78, in handle_async_request
    stream = await self._connect(request)
             ^^^^^^^^^^^^^^^^^^^^^^^^^^^^
  File "C:\Users\dayour\AppData\Local\Programs\Python\Python312\Lib\site-packages\httpcore\_async\connection.py", line 124, in _connect
    stream = await self._network_backend.connect_tcp(**kwargs)
             ^^^^^^^^^^^^^^^^^^^^^^^^^^^^^^^^^^^^^^^^^^^^^^^^^
  File "C:\Users\dayour\AppData\Local\Programs\Python\Python312\Lib\site-packages\httpcore\_backends\auto.py", line 31, in connect_tcp
    return await self._backend.connect_tcp(
           ^^^^^^^^^^^^^^^^^^^^^^^^^^^^^^^^
  File "C:\Users\dayour\AppData\Local\Programs\Python\Python312\Lib\site-packages\httpcore\_backends\anyio.py", line 113, in connect_tcp
    with map_exceptions(exc_map):
         ^^^^^^^^^^^^^^^^^^^^^^^
  File "C:\Users\dayour\AppData\Local\Programs\Python\Python312\Lib\contextlib.py", line 158, in __exit__
    self.gen.throw(value)
  File "C:\Users\dayour\AppData\Local\Programs\Python\Python312\Lib\site-packages\httpcore\_exceptions.py", line 14, in map_exceptions
    raise to_exc(exc) from exc
httpcore.ConnectError: All connection attempts failed

The above exception was the direct cause of the following exception:

Traceback (most recent call last):
  File "D:\0GH_PROD\Darbot-Agent-Engine\src\frontend\frontend_server.py", line 109, in api_proxy
    response = await client.request(
               ^^^^^^^^^^^^^^^^^^^^^
  File "C:\Users\dayour\AppData\Local\Programs\Python\Python312\Lib\site-packages\httpx\_client.py", line 1540, in request
    return await self.send(request, auth=auth, follow_redirects=follow_redirects)
           ^^^^^^^^^^^^^^^^^^^^^^^^^^^^^^^^^^^^^^^^^^^^^^^^^^^^^^^^^^^^^^^^^^^^^^
  File "C:\Users\dayour\AppData\Local\Programs\Python\Python312\Lib\site-packages\httpx\_client.py", line 1629, in send
    response = await self._send_handling_auth(
               ^^^^^^^^^^^^^^^^^^^^^^^^^^^^^^^
  File "C:\Users\dayour\AppData\Local\Programs\Python\Python312\Lib\site-packages\httpx\_client.py", line 1657, in _send_handling_auth
    response = await self._send_handling_redirects(
               ^^^^^^^^^^^^^^^^^^^^^^^^^^^^^^^^^^^^
  File "C:\Users\dayour\AppData\Local\Programs\Python\Python312\Lib\site-packages\httpx\_client.py", line 1694, in _send_handling_redirects
    response = await self._send_single_request(request)
               ^^^^^^^^^^^^^^^^^^^^^^^^^^^^^^^^^^^^^^^^
  File "C:\Users\dayour\AppData\Local\Programs\Python\Python312\Lib\site-packages\httpx\_client.py", line 1730, in _send_single_request
    response = await transport.handle_async_request(request)
               ^^^^^^^^^^^^^^^^^^^^^^^^^^^^^^^^^^^^^^^^^^^^^
  File "C:\Users\dayour\AppData\Local\Programs\Python\Python312\Lib\site-packages\httpx\_transports\default.py", line 393, in handle_async_request
    with map_httpcore_exceptions():
         ^^^^^^^^^^^^^^^^^^^^^^^^^
  File "C:\Users\dayour\AppData\Local\Programs\Python\Python312\Lib\contextlib.py", line 158, in __exit__
    self.gen.throw(value)
  File "C:\Users\dayour\AppData\Local\Programs\Python\Python312\Lib\site-packages\httpx\_transports\default.py", line 118, in map_httpcore_exceptions
    raise mapped_exc(message) from exc
httpx.ConnectError: All connection attempts failed
2025-06-01 23:39:56,669 - root - INFO - Proxying GET request to: http://localhost:8001/api/plans
2025-06-01 23:39:56,670 - root - INFO - Query params: {}
2025-06-01 23:39:56,670 - root - INFO - Headers: {'connection': 'keep-alive', 'sec-ch-ua-platform': '"Windows"', 'x-ms-client-principal-id': '12345678-abcd-efgh-ijkl-9876543210ab', 'x-ms-client-principal-name': 'Local User', 'sec-ch-ua': '"Not.A/Brand";v="99", "Chromium";v="136"', 'x-ms-client-principal-idp': 'mock-identity-provider', 'sec-ch-ua-mobile': '?0', 'x-ms-client-principal': 'mock-client-principal-id', 'user-agent': 'Mozilla/5.0 (Windows NT 10.0; Win64; x64) AppleWebKit/537.36 (KHTML, like Gecko) Chrome/136.0.0.0 Safari/537.36', 'content-type': 'application/json', 'accept': '*/*', 'sec-fetch-site': 'same-origin', 'sec-fetch-mode': 'cors', 'sec-fetch-dest': 'empty', 'referer': 'http://localhost:3000/app.html?v=home', 'accept-encoding': 'gzip, deflate, br, zstd', 'accept-language': 'en-US,en;q=0.9'}
2025-06-01 23:39:59,172 - root - ERROR - Proxy error: All connection attempts failed
Traceback (most recent call last):
  File "C:\Users\dayour\AppData\Local\Programs\Python\Python312\Lib\site-packages\httpx\_transports\default.py", line 101, in map_httpcore_exceptions
    yield
  File "C:\Users\dayour\AppData\Local\Programs\Python\Python312\Lib\site-packages\httpx\_transports\default.py", line 394, in handle_async_request
    resp = await self._pool.handle_async_request(req)
           ^^^^^^^^^^^^^^^^^^^^^^^^^^^^^^^^^^^^^^^^^^
  File "C:\Users\dayour\AppData\Local\Programs\Python\Python312\Lib\site-packages\httpcore\_async\connection_pool.py", line 256, in handle_async_request
    raise exc from None
  File "C:\Users\dayour\AppData\Local\Programs\Python\Python312\Lib\site-packages\httpcore\_async\connection_pool.py", line 236, in handle_async_request
    response = await connection.handle_async_request(
               ^^^^^^^^^^^^^^^^^^^^^^^^^^^^^^^^^^^^^^
  File "C:\Users\dayour\AppData\Local\Programs\Python\Python312\Lib\site-packages\httpcore\_async\connection.py", line 101, in handle_async_request
    raise exc
  File "C:\Users\dayour\AppData\Local\Programs\Python\Python312\Lib\site-packages\httpcore\_async\connection.py", line 78, in handle_async_request
    stream = await self._connect(request)
             ^^^^^^^^^^^^^^^^^^^^^^^^^^^^
  File "C:\Users\dayour\AppData\Local\Programs\Python\Python312\Lib\site-packages\httpcore\_async\connection.py", line 124, in _connect
    stream = await self._network_backend.connect_tcp(**kwargs)
             ^^^^^^^^^^^^^^^^^^^^^^^^^^^^^^^^^^^^^^^^^^^^^^^^^
  File "C:\Users\dayour\AppData\Local\Programs\Python\Python312\Lib\site-packages\httpcore\_backends\auto.py", line 31, in connect_tcp
    return await self._backend.connect_tcp(
           ^^^^^^^^^^^^^^^^^^^^^^^^^^^^^^^^
  File "C:\Users\dayour\AppData\Local\Programs\Python\Python312\Lib\site-packages\httpcore\_backends\anyio.py", line 113, in connect_tcp
    with map_exceptions(exc_map):
         ^^^^^^^^^^^^^^^^^^^^^^^
  File "C:\Users\dayour\AppData\Local\Programs\Python\Python312\Lib\contextlib.py", line 158, in __exit__
    self.gen.throw(value)
  File "C:\Users\dayour\AppData\Local\Programs\Python\Python312\Lib\site-packages\httpcore\_exceptions.py", line 14, in map_exceptions
    raise to_exc(exc) from exc
httpcore.ConnectError: All connection attempts failed

The above exception was the direct cause of the following exception:

Traceback (most recent call last):
  File "D:\0GH_PROD\Darbot-Agent-Engine\src\frontend\frontend_server.py", line 109, in api_proxy
    response = await client.request(
               ^^^^^^^^^^^^^^^^^^^^^
  File "C:\Users\dayour\AppData\Local\Programs\Python\Python312\Lib\site-packages\httpx\_client.py", line 1540, in request
    return await self.send(request, auth=auth, follow_redirects=follow_redirects)
           ^^^^^^^^^^^^^^^^^^^^^^^^^^^^^^^^^^^^^^^^^^^^^^^^^^^^^^^^^^^^^^^^^^^^^^
  File "C:\Users\dayour\AppData\Local\Programs\Python\Python312\Lib\site-packages\httpx\_client.py", line 1629, in send
    response = await self._send_handling_auth(
               ^^^^^^^^^^^^^^^^^^^^^^^^^^^^^^^
  File "C:\Users\dayour\AppData\Local\Programs\Python\Python312\Lib\site-packages\httpx\_client.py", line 1657, in _send_handling_auth
    response = await self._send_handling_redirects(
               ^^^^^^^^^^^^^^^^^^^^^^^^^^^^^^^^^^^^
  File "C:\Users\dayour\AppData\Local\Programs\Python\Python312\Lib\site-packages\httpx\_client.py", line 1694, in _send_handling_redirects
    response = await self._send_single_request(request)
               ^^^^^^^^^^^^^^^^^^^^^^^^^^^^^^^^^^^^^^^^
  File "C:\Users\dayour\AppData\Local\Programs\Python\Python312\Lib\site-packages\httpx\_client.py", line 1730, in _send_single_request
    response = await transport.handle_async_request(request)
               ^^^^^^^^^^^^^^^^^^^^^^^^^^^^^^^^^^^^^^^^^^^^^
  File "C:\Users\dayour\AppData\Local\Programs\Python\Python312\Lib\site-packages\httpx\_transports\default.py", line 393, in handle_async_request
    with map_httpcore_exceptions():
         ^^^^^^^^^^^^^^^^^^^^^^^^^
  File "C:\Users\dayour\AppData\Local\Programs\Python\Python312\Lib\contextlib.py", line 158, in __exit__
    self.gen.throw(value)
  File "C:\Users\dayour\AppData\Local\Programs\Python\Python312\Lib\site-packages\httpx\_transports\default.py", line 118, in map_httpcore_exceptions
    raise mapped_exc(message) from exc
httpx.ConnectError: All connection attempts failed
2025-06-01 23:39:59,179 - root - INFO - Proxying GET request to: http://localhost:8001/api/plans
2025-06-01 23:39:59,179 - root - INFO - Query params: {}
2025-06-01 23:39:59,179 - root - INFO - Headers: {'connection': 'keep-alive', 'sec-ch-ua-platform': '"Windows"', 'x-ms-client-principal-id': '12345678-abcd-efgh-ijkl-9876543210ab', 'x-ms-client-principal-name': 'Local User', 'sec-ch-ua': '"Not.A/Brand";v="99", "Chromium";v="136"', 'x-ms-client-principal-idp': 'mock-identity-provider', 'sec-ch-ua-mobile': '?0', 'x-ms-client-principal': 'mock-client-principal-id', 'user-agent': 'Mozilla/5.0 (Windows NT 10.0; Win64; x64) AppleWebKit/537.36 (KHTML, like Gecko) Chrome/136.0.0.0 Safari/537.36', 'content-type': 'application/json', 'accept': '*/*', 'sec-fetch-site': 'same-origin', 'sec-fetch-mode': 'cors', 'sec-fetch-dest': 'empty', 'referer': 'http://localhost:3000/app.html?v=home', 'accept-encoding': 'gzip, deflate, br, zstd', 'accept-language': 'en-US,en;q=0.9'}
2025-06-01 23:40:01,688 - root - ERROR - Proxy error: All connection attempts failed
Traceback (most recent call last):
  File "C:\Users\dayour\AppData\Local\Programs\Python\Python312\Lib\site-packages\httpx\_transports\default.py", line 101, in map_httpcore_exceptions
    yield
  File "C:\Users\dayour\AppData\Local\Programs\Python\Python312\Lib\site-packages\httpx\_transports\default.py", line 394, in handle_async_request
    resp = await self._pool.handle_async_request(req)
           ^^^^^^^^^^^^^^^^^^^^^^^^^^^^^^^^^^^^^^^^^^
  File "C:\Users\dayour\AppData\Local\Programs\Python\Python312\Lib\site-packages\httpcore\_async\connection_pool.py", line 256, in handle_async_request
    raise exc from None
  File "C:\Users\dayour\AppData\Local\Programs\Python\Python312\Lib\site-packages\httpcore\_async\connection_pool.py", line 236, in handle_async_request
    response = await connection.handle_async_request(
               ^^^^^^^^^^^^^^^^^^^^^^^^^^^^^^^^^^^^^^
  File "C:\Users\dayour\AppData\Local\Programs\Python\Python312\Lib\site-packages\httpcore\_async\connection.py", line 101, in handle_async_request
    raise exc
  File "C:\Users\dayour\AppData\Local\Programs\Python\Python312\Lib\site-packages\httpcore\_async\connection.py", line 78, in handle_async_request
    stream = await self._connect(request)
             ^^^^^^^^^^^^^^^^^^^^^^^^^^^^
  File "C:\Users\dayour\AppData\Local\Programs\Python\Python312\Lib\site-packages\httpcore\_async\connection.py", line 124, in _connect
    stream = await self._network_backend.connect_tcp(**kwargs)
             ^^^^^^^^^^^^^^^^^^^^^^^^^^^^^^^^^^^^^^^^^^^^^^^^^
  File "C:\Users\dayour\AppData\Local\Programs\Python\Python312\Lib\site-packages\httpcore\_backends\auto.py", line 31, in connect_tcp
    return await self._backend.connect_tcp(
           ^^^^^^^^^^^^^^^^^^^^^^^^^^^^^^^^
  File "C:\Users\dayour\AppData\Local\Programs\Python\Python312\Lib\site-packages\httpcore\_backends\anyio.py", line 113, in connect_tcp
    with map_exceptions(exc_map):
         ^^^^^^^^^^^^^^^^^^^^^^^
  File "C:\Users\dayour\AppData\Local\Programs\Python\Python312\Lib\contextlib.py", line 158, in __exit__
    self.gen.throw(value)
  File "C:\Users\dayour\AppData\Local\Programs\Python\Python312\Lib\site-packages\httpcore\_exceptions.py", line 14, in map_exceptions
    raise to_exc(exc) from exc
httpcore.ConnectError: All connection attempts failed

The above exception was the direct cause of the following exception:

Traceback (most recent call last):
  File "D:\0GH_PROD\Darbot-Agent-Engine\src\frontend\frontend_server.py", line 109, in api_proxy
    response = await client.request(
               ^^^^^^^^^^^^^^^^^^^^^
  File "C:\Users\dayour\AppData\Local\Programs\Python\Python312\Lib\site-packages\httpx\_client.py", line 1540, in request
    return await self.send(request, auth=auth, follow_redirects=follow_redirects)
           ^^^^^^^^^^^^^^^^^^^^^^^^^^^^^^^^^^^^^^^^^^^^^^^^^^^^^^^^^^^^^^^^^^^^^^
  File "C:\Users\dayour\AppData\Local\Programs\Python\Python312\Lib\site-packages\httpx\_client.py", line 1629, in send
    response = await self._send_handling_auth(
               ^^^^^^^^^^^^^^^^^^^^^^^^^^^^^^^
  File "C:\Users\dayour\AppData\Local\Programs\Python\Python312\Lib\site-packages\httpx\_client.py", line 1657, in _send_handling_auth
    response = await self._send_handling_redirects(
               ^^^^^^^^^^^^^^^^^^^^^^^^^^^^^^^^^^^^
  File "C:\Users\dayour\AppData\Local\Programs\Python\Python312\Lib\site-packages\httpx\_client.py", line 1694, in _send_handling_redirects
    response = await self._send_single_request(request)
               ^^^^^^^^^^^^^^^^^^^^^^^^^^^^^^^^^^^^^^^^
  File "C:\Users\dayour\AppData\Local\Programs\Python\Python312\Lib\site-packages\httpx\_client.py", line 1730, in _send_single_request
    response = await transport.handle_async_request(request)
               ^^^^^^^^^^^^^^^^^^^^^^^^^^^^^^^^^^^^^^^^^^^^^
  File "C:\Users\dayour\AppData\Local\Programs\Python\Python312\Lib\site-packages\httpx\_transports\default.py", line 393, in handle_async_request
    with map_httpcore_exceptions():
         ^^^^^^^^^^^^^^^^^^^^^^^^^
  File "C:\Users\dayour\AppData\Local\Programs\Python\Python312\Lib\contextlib.py", line 158, in __exit__
    self.gen.throw(value)
  File "C:\Users\dayour\AppData\Local\Programs\Python\Python312\Lib\site-packages\httpx\_transports\default.py", line 118, in map_httpcore_exceptions
    raise mapped_exc(message) from exc
httpx.ConnectError: All connection attempts failed
INFO:     Shutting down
INFO:     Waiting for application shutdown.
INFO:     Application shutdown complete.
INFO:     Finished server process [69836]
